Workbook

Sheet DCF
A1: WEGE3 · Modelo DCF
A2: Exportado do Gab's FinLab em 10/08/2026 · dados: DFP/ITR da CVM e mercado (BRAPI) · não é recomendação de investimento
A3: Legenda: fundo amarelo + fonte azul = edite aqui · fonte preta = fórmula, não mexa · fundo cinza = dado do painel
A5: DADOS DO PAINEL | C5: Fonte
A6: FCL médio 3 anos (R$ mi) | B6: 4800 | C6: DFC da CVM 2023–2025
A7: FCL último exercício (R$ mi) | B7: 5600 | C7: DFC da CVM 2025
A8: Dívida líquida (R$ mi) | B8: -3100 | C8: DFP 2025 (caixa líquido)
A9: Ações emitidas (mi) | B9: 4196 | C9: capital social CVM
A10: Preço de tela (R$) | B10: 41.2 | C10: BRAPI · 10/08/2026
A12: PREMISSAS POR CENÁRIO | B12: Pessimista | C12: Mediana | D12: Otimista
A13: FCL base (R$ mi) | B13: 4800 | C13: 4800 | D13: 4800 | F13: padrão: média de 3 anos (B6); troque por B7 se preferir o último exercício
A14: Crescimento do FCL · ano 1 | B14: 0.06 | C14: 0.12 | D14: 0.18
A15: Crescimento · ano 2 | B15: 0.05 | C15: 0.105 | D15: 0.16
A16: Crescimento · ano 3 | B16: 0.045 | C16: 0.09 | D16: 0.14
A17: Crescimento · ano 4 | B17: 0.04 | C17: 0.08 | D17: 0.12
A18: Crescimento · ano 5 | B18: 0.035 | C18: 0.07 | D18: 0.1
A19: Perpetuidade (g) | B19: 0.035 | C19: 0.05 | D19: 0.065 | F19: dificilmente acima de inflação + PIB
A20: Taxa livre de risco (Rf) | B20: 0.131 | C20: 0.131 | D20: 0.131 | F20: prefixado ~10 anos (ANBIMA)
A21: Beta | B21: 0.8 | C21: 0.72 | D21: 0.65
A22: Prêmio de risco (ERP) | B22: 0.045 | C22: 0.045 | D22: 0.045
A23: Prêmio adicional | B23: 0.01 | C23: 0 | D23: 0 | F23: tamanho, governança, execução
A24: Spread de crédito | B24: 0.015 | C24: 0.015 | D24: 0.015
A25: Dívida / (dívida + equity) | B25: 0.05 | C25: 0.05 | D25: 0.05
A26: Alíquota efetiva | B26: 0.2 | C26: 0.2 | D26: 0.2
A28: CUSTO DE CAPITAL
A29: Ke — custo do equity | B29: =B20+B21*B22+B23 -> 0.177 | C29: =C20+C21*C22+C23 -> 0.1634 | D29: =D20+D21*D22+D23 -> 0.16025
A30: Kd líquido de impostos | B30: =(B20+B24)*(1-B26) -> 0.1168 | C30: =(C20+C24)*(1-C26) -> 0.1168 | D30: =(D20+D24)*(1-D26) -> 0.1168
A31: WACC | B31: =B29*(1-B25)+B30*B25 -> 0.17399 | C31: =C29*(1-C25)+C30*C25 -> 0.16107 | D31: =D29*(1-D25)+D30*D25 -> 0.1580775
A33: PROJEÇÃO DO FCL (R$ mi)
A34: FCL ano 1 (2025+1) | B34: =B13*(1+B14) -> 5088 | C34: =C13*(1+C14) -> 5376 | D34: =D13*(1+D14) -> 5664
A35: FCL ano 2 (2025+2) | B35: =B34*(1+B15) -> 5342.4 | C35: =C34*(1+C15) -> 5940.48 | D35: =D34*(1+D15) -> 6570.24
A36: FCL ano 3 (2025+3) | B36: =B35*(1+B16) -> 5582.808 | C36: =C35*(1+C16) -> 6475.1232 | D36: =D35*(1+D16) -> 7490.0736
A37: FCL ano 4 (2025+4) | B37: =B36*(1+B17) -> 5806.1203 | C37: =C36*(1+C17) -> 6993.1331 | D37: =D36*(1+D17) -> 8388.8824
A38: FCL ano 5 (2025+5) | B38: =B37*(1+B18) -> 6009.3345 | C38: =C37*(1+C18) -> 7482.6524 | D38: =D37*(1+D18) -> 9227.7707
A40: DO FLUXO AO PREÇO JUSTO
A41: VP do ano 1 | B41: =B34/(1+B$31)^1 -> 4333.9381 | C41: =C34/(1+C$31)^1 -> 4630.2118 | D41: =D34/(1+D$31)^1 -> 4890.8644
A42: VP do ano 2 | B42: =B35/(1+B$31)^2 -> 3876.2128 | C42: =C35/(1+C$31)^2 -> 4406.6112 | D42: =D35/(1+D$31)^2 -> 4898.9836
A43: VP do ano 3 | B43: =B36/(1+B$31)^3 -> 3450.321 | C43: =C36/(1+C$31)^3 -> 4136.8791 | D43: =D36/(1+D$31)^3 -> 4822.5109
A44: VP do ano 4 | B44: =B37/(1+B$31)^4 -> 3056.5284 | C44: =C37/(1+C$31)^4 -> 3848.0276 | D44: =D37/(1+D$31)^4 -> 4663.9471
A45: VP do ano 5 | B45: =B38/(1+B$31)^5 -> 2694.6626 | C45: =C38/(1+C$31)^5 -> 3546.2027 | D45: =D38/(1+D$31)^5 -> 4430.0505
...

Sheet Sensibilidade
A1: Sensibilidade do preço justo (R$/ação)
A2: Fluxos do cenário Mediana (aba DCF, coluna C) · linhas: WACC · colunas: crescimento na perpetuidade
A4: WACC \ g | B4: 0.03 | C4: 0.04 | D4: 0.05 | E4: 0.06 | F4: 0.07
A5: 0.13 | B5: =IF($A5<=B$4,"n/a",(DCF!$C$34/(1+$A5)^1+DCF!$C$35/(1+$A5)^2+DCF!$C$36/(1+$A5)^3+DCF!$C$37/(1+$A5)^4+DCF!$C$38/(1+$A5)^5+DCF!$C$38*(1+B$4)/($A5-B$4)/(1+$A5)^5-DCF!$B$8)/DCF!$B$9) -> 16.010225 | C5: =IF($A5<=C$4,"n/a",(DCF!$C$34/(1+$A5)^1+DCF!$C$35/(1+$A5)^2+DCF!$C$36/(1+$A5)^3+DCF!$C$37/(1+$A5)^4+DCF!$C$38/(1+$A5)^5+DCF!$C$38*(1+C$4)/($A5-C$4)/(1+$A5)^5-DCF!$B$8)/DCF!$B$9) -> 17.225469 | D5: =IF($A5<=D$4,"n/a",(DCF!$C$34/(1+$A5)^1+DCF!$C$35/(1+$A5)^2+DCF!$C$36/(1+$A5)^3+DCF!$C$37/(1+$A5)^4+DCF!$C$38/(1+$A5)^5+DCF!$C$38*(1+D$4)/($A5-D$4)/(1+$A5)^5-DCF!$B$8)/DCF!$B$9) -> 18.744526 | E5: =IF($A5<=E$4,"n/a",(DCF!$C$34/(1+$A5)^1+DCF!$C$35/(1+$A5)^2+DCF!$C$36/(1+$A5)^3+DCF!$C$37/(1+$A5)^4+DCF!$C$38/(1+$A5)^5+DCF!$C$38*(1+E$4)/($A5-E$4)/(1+$A5)^5-DCF!$B$8)/DCF!$B$9) -> 20.697598 | F5: =IF($A5<=F$4,"n/a",(DCF!$C$34/(1+$A5)^1+DCF!$C$35/(1+$A5)^2+DCF!$C$36/(1+$A5)^3+DCF!$C$37/(1+$A5)^4+DCF!$C$38/(1+$A5)^5+DCF!$C$38*(1+F$4)/($A5-F$4)/(1+$A5)^5-DCF!$B$8)/DCF!$B$9) -> 23.301694
A6: 0.14 | B6: =IF($A6<=B$4,"n/a",(DCF!$C$34/(1+$A6)^1+DCF!$C$35/(1+$A6)^2+DCF!$C$36/(1+$A6)^3+DCF!$C$37/(1+$A6)^4+DCF!$C$38/(1+$A6)^5+DCF!$C$38*(1+B$4)/($A6-B$4)/(1+$A6)^5-DCF!$B$8)/DCF!$B$9) -> 14.579016 | C6: =IF($A6<=C$4,"n/a",(DCF!$C$34/(1+$A6)^1+DCF!$C$35/(1+$A6)^2+DCF!$C$36/(1+$A6)^3+DCF!$C$37/(1+$A6)^4+DCF!$C$38/(1+$A6)^5+DCF!$C$38*(1+C$4)/($A6-C$4)/(1+$A6)^5-DCF!$B$8)/DCF!$B$9) -> 15.538876 | D6: =IF($A6<=D$4,"n/a",(DCF!$C$34/(1+$A6)^1+DCF!$C$35/(1+$A6)^2+DCF!$C$36/(1+$A6)^3+DCF!$C$37/(1+$A6)^4+DCF!$C$38/(1+$A6)^5+DCF!$C$38*(1+D$4)/($A6-D$4)/(1+$A6)^5-DCF!$B$8)/DCF!$B$9) -> 16.712039 | E6: =IF($A6<=E$4,"n/a",(DCF!$C$34/(1+$A6)^1+DCF!$C$35/(1+$A6)^2+DCF!$C$36/(1+$A6)^3+DCF!$C$37/(1+$A6)^4+DCF!$C$38/(1+$A6)^5+DCF!$C$38*(1+E$4)/($A6-E$4)/(1+$A6)^5-DCF!$B$8)/DCF!$B$9) -> 18.178492 | F6: =IF($A6<=F$4,"n/a",(DCF!$C$34/(1+$A6)^1+DCF!$C$35/(1+$A6)^2+DCF!$C$36/(1+$A6)^3+DCF!$C$37/(1+$A6)^4+DCF!$C$38/(1+$A6)^5+DCF!$C$38*(1+F$4)/($A6-F$4)/(1+$A6)^5-DCF!$B$8)/DCF!$B$9) -> 20.063932
A7: 0.15 | B7: =IF($A7<=B$4,"n/a",(DCF!$C$34/(1+$A7)^1+DCF!$C$35/(1+$A7)^2+DCF!$C$36/(1+$A7)^3+DCF!$C$37/(1+$A7)^4+DCF!$C$38/(1+$A7)^5+DCF!$C$38*(1+B$4)/($A7-B$4)/(1+$A7)^5-DCF!$B$8)/DCF!$B$9) -> 13.387609 | C7: =IF($A7<=C$4,"n/a",(DCF!$C$34/(1+$A7)^1+DCF!$C$35/(1+$A7)^2+DCF!$C$36/(1+$A7)^3+DCF!$C$37/(1+$A7)^4+DCF!$C$38/(1+$A7)^5+DCF!$C$38*(1+C$4)/($A7-C$4)/(1+$A7)^5-DCF!$B$8)/DCF!$B$9) -> 14.160031 | D7: =IF($A7<=D$4,"n/a",(DCF!$C$34/(1+$A7)^1+DCF!$C$35/(1+$A7)^2+DCF!$C$36/(1+$A7)^3+DCF!$C$37/(1+$A7)^4+DCF!$C$38/(1+$A7)^5+DCF!$C$38*(1+D$4)/($A7-D$4)/(1+$A7)^5-DCF!$B$8)/DCF!$B$9) -> 15.086938 | E7: =IF($A7<=E$4,"n/a",(DCF!$C$34/(1+$A7)^1+DCF!$C$35/(1+$A7)^2+DCF!$C$36/(1+$A7)^3+DCF!$C$37/(1+$A7)^4+DCF!$C$38/(1+$A7)^5+DCF!$C$38*(1+E$4)/($A7-E$4)/(1+$A7)^5-DCF!$B$8)/DCF!$B$9) -> 16.219824 | F7: =IF($A7<=F$4,"n/a",(DCF!$C$34/(1+$A7)^1+DCF!$C$35/(1+$A7)^2+DCF!$C$36/(1+$A7)^3+DCF!$C$37/(1+$A7)^4+DCF!$C$38/(1+$A7)^5+DCF!$C$38*(1+F$4)/($A7-F$4)/(1+$A7)^5-DCF!$B$8)/DCF!$B$9) -> 17.635932
A8: 0.16 | B8: =IF($A8<=B$4,"n/a",(DCF!$C$34/(1+$A8)^1+DCF!$C$35/(1+$A8)^2+DCF!$C$36/(1+$A8)^3+DCF!$C$37/(1+$A8)^4+DCF!$C$38/(1+$A8)^5+DCF!$C$38*(1+B$4)/($A8-B$4)/(1+$A8)^5-DCF!$B$8)/DCF!$B$9) -> 12.380614 | C8: =IF($A8<=C$4,"n/a",(DCF!$C$34/(1+$A8)^1+DCF!$C$35/(1+$A8)^2+DCF!$C$36/(1+$A8)^3+DCF!$C$37/(1+$A8)^4+DCF!$C$38/(1+$A8)^5+DCF!$C$38*(1+C$4)/($A8-C$4)/(1+$A8)^5-DCF!$B$8)/DCF!$B$9) -> 13.011955 | D8: =IF($A8<=D$4,"n/a",(DCF!$C$34/(1+$A8)^1+DCF!$C$35/(1+$A8)^2+DCF!$C$36/(1+$A8)^3+DCF!$C$37/(1+$A8)^4+DCF!$C$38/(1+$A8)^5+DCF!$C$38*(1+D$4)/($A8-D$4)/(1+$A8)^5-DCF!$B$8)/DCF!$B$9) -> 13.758084 | E8: =IF($A8<=E$4,"n/a",(DCF!$C$34/(1+$A8)^1+DCF!$C$35/(1+$A8)^2+DCF!$C$36/(1+$A8)^3+DCF!$C$37/(1+$A8)^4+DCF!$C$38/(1+$A8)^5+DCF!$C$38*(1+E$4)/($A8-E$4)/(1+$A8)^5-DCF!$B$8)/DCF!$B$9) -> 14.65344 | F8: =IF($A8<=F$4,"n/a",(DCF!$C$34/(1+$A8)^1+DCF!$C$35/(1+$A8)^2+DCF!$C$36/(1+$A8)^3+DCF!$C$37/(1+$A8)^4+DCF!$C$38/(1+$A8)^5+DCF!$C$38*(1+F$4)/($A8-F$4)/(1+$A8)^5-DCF!$B$8)/DCF!$B$9) -> 15.747763
A9: 0.17 | B9: =IF($A9<=B$4,"n/a",(DCF!$C$34/(1+$A9)^1+DCF!$C$35/(1+$A9)^2+DCF!$C$36/(1+$A9)^3+DCF!$C$37/(1+$A9)^4+DCF!$C$38/(1+$A9)^5+DCF!$C$38*(1+B$4)/($A9-B$4)/(1+$A9)^5-DCF!$B$8)/DCF!$B$9) -> 11.518471 | C9: =IF($A9<=C$4,"n/a",(DCF!$C$34/(1+$A9)^1+DCF!$C$35/(1+$A9)^2+DCF!$C$36/(1+$A9)^3+DCF!$C$37/(1+$A9)^4+DCF!$C$38/(1+$A9)^5+DCF!$C$38*(1+C$4)/($A9-C$4)/(1+$A9)^5-DCF!$B$8)/DCF!$B$9) -> 12.041355 | D9: =IF($A9<=D$4,"n/a",(DCF!$C$34/(1+$A9)^1+DCF!$C$35/(1+$A9)^2+DCF!$C$36/(1+$A9)^3+DCF!$C$37/(1+$A9)^4+DCF!$C$38/(1+$A9)^5+DCF!$C$38*(1+D$4)/($A9-D$4)/(1+$A9)^5-DCF!$B$8)/DCF!$B$9) -> 12.651386 | E9: =IF($A9<=E$4,"n/a",(DCF!$C$34/(1+$A9)^1+DCF!$C$35/(1+$A9)^2+DCF!$C$36/(1+$A9)^3+DCF!$C$37/(1+$A9)^4+DCF!$C$38/(1+$A9)^5+DCF!$C$38*(1+E$4)/($A9-E$4)/(1+$A9)^5-DCF!$B$8)/DCF!$B$9) -> 13.372332 | F9: =IF($A9<=F$4,"n/a",(DCF!$C$34/(1+$A9)^1+DCF!$C$35/(1+$A9)^2+DCF!$C$36/(1+$A9)^3+DCF!$C$37/(1+$A9)^4+DCF!$C$38/(1+$A9)^5+DCF!$C$38*(1+F$4)/($A9-F$4)/(1+$A9)^5-DCF!$B$8)/DCF!$B$9) -> 14.237467
A10: 0.18 | B10: =IF($A10<=B$4,"n/a",(DCF!$C$34/(1+$A10)^1+DCF!$C$35/(1+$A10)^2+DCF!$C$36/(1+$A10)^3+DCF!$C$37/(1+$A10)^4+DCF!$C$38/(1+$A10)^5+DCF!$C$38*(1+B$4)/($A10-B$4)/(1+$A10)^5-DCF!$B$8)/DCF!$B$9) -> 10.77217 | C10: =IF($A10<=C$4,"n/a",(DCF!$C$34/(1+$A10)^1+DCF!$C$35/(1+$A10)^2+DCF!$C$36/(1+$A10)^3+DCF!$C$37/(1+$A10)^4+DCF!$C$38/(1+$A10)^5+DCF!$C$38*(1+C$4)/($A10-C$4)/(1+$A10)^5-DCF!$B$8)/DCF!$B$9) -> 11.210169 | D10: =IF($A10<=D$4,"n/a",(DCF!$C$34/(1+$A10)^1+DCF!$C$35/(1+$A10)^2+DCF!$C$36/(1+$A10)^3+DCF!$C$37/(1+$A10)^4+DCF!$C$38/(1+$A10)^5+DCF!$C$38*(1+D$4)/($A10-D$4)/(1+$A10)^5-DCF!$B$8)/DCF!$B$9) -> 11.715552 | E10: =IF($A10<=E$4,"n/a",(DCF!$C$34/(1+$A10)^1+DCF!$C$35/(1+$A10)^2+DCF!$C$36/(1+$A10)^3+DCF!$C$37/(1+$A10)^4+DCF!$C$38/(1+$A10)^5+DCF!$C$38*(1+E$4)/($A10-E$4)/(1+$A10)^5-DCF!$B$8)/DCF!$B$9) -> 12.305165 | F10: =IF($A10<=F$4,"n/a",(DCF!$C$34/(1+$A10)^1+DCF!$C$35/(1+$A10)^2+DCF!$C$36/(1+$A10)^3+DCF!$C$37/(1+$A10)^4+DCF!$C$38/(1+$A10)^5+DCF!$C$38*(1+F$4)/($A10-F$4)/(1+$A10)^5-DCF!$B$8)/DCF!$B$9) -> 13.001981
A11: 0.19 | B11: =IF($A11<=B$4,"n/a",(DCF!$C$34/(1+$A11)^1+DCF!$C$35/(1+$A11)^2+DCF!$C$36/(1+$A11)^3+DCF!$C$37/(1+$A11)^4+DCF!$C$38/(1+$A11)^5+DCF!$C$38*(1+B$4)/($A11-B$4)/(1+$A11)^5-DCF!$B$8)/DCF!$B$9) -> 10.119955 | C11: =IF($A11<=C$4,"n/a",(DCF!$C$34/(1+$A11)^1+DCF!$C$35/(1+$A11)^2+DCF!$C$36/(1+$A11)^3+DCF!$C$37/(1+$A11)^4+DCF!$C$38/(1+$A11)^5+DCF!$C$38*(1+C$4)/($A11-C$4)/(1+$A11)^5-DCF!$B$8)/DCF!$B$9) -> 10.490483 | D11: =IF($A11<=D$4,"n/a",(DCF!$C$34/(1+$A11)^1+DCF!$C$35/(1+$A11)^2+DCF!$C$36/(1+$A11)^3+DCF!$C$37/(1+$A11)^4+DCF!$C$38/(1+$A11)^5+DCF!$C$38*(1+D$4)/($A11-D$4)/(1+$A11)^5-DCF!$B$8)/DCF!$B$9) -> 10.913944 | E11: =IF($A11<=E$4,"n/a",(DCF!$C$34/(1+$A11)^1+DCF!$C$35/(1+$A11)^2+DCF!$C$36/(1+$A11)^3+DCF!$C$37/(1+$A11)^4+DCF!$C$38/(1+$A11)^5+DCF!$C$38*(1+E$4)/($A11-E$4)/(1+$A11)^5-DCF!$B$8)/DCF!$B$9) -> 11.402552 | F11: =IF($A11<=F$4,"n/a",(DCF!$C$34/(1+$A11)^1+DCF!$C$35/(1+$A11)^2+DCF!$C$36/(1+$A11)^3+DCF!$C$37/(1+$A11)^4+DCF!$C$38/(1+$A11)^5+DCF!$C$38*(1+F$4)/($A11-F$4)/(1+$A11)^5-DCF!$B$8)/DCF!$B$9) -> 11.972595
A13: A célula mais próxima do seu WACC e do seu g na aba DCF é o seu caso-base.
